Workbook

Sheet Léame
B2: Encuesta de Cultura de Salud, Seguridad y Ambiente 2026 — libro de respuestas
B3: Cada respuesta de la encuesta (https://zuicagerman-eng.github.io/Encuesta-Cultura-y-seguradad/) llega como una fila nueva, igual que en Google Forms.
B5: Hojas
B6: Respuestas de formulario 1 — una fila por persona, con las 46 columnas del Form en el mismo orden. La escribe la encuesta: no la edite a mano.
B7: Reportes de problemas — lo que la gente envía desde el botón Ayuda. Use la columna Estado para hacer seguimiento.
B8: Resumen — total de respuestas, respuestas por planta, vinculación y cargo, y % favorable por dimensión. Se actualiza solo.
B9: Diccionario — qué es cada columna y qué valores puede tener.
B11: Cómo conectarlo
B12: 1. Suba este archivo a Google Drive y ábralo con Google Sheets (Archivo → Guardar como Hojas de cálculo de Google).
B13: 2. En la hoja de Google: Extensiones → Apps Script. Pegue apps-script/Codigo.gs del repositorio y guarde.
B14: 3. Ejecute la función prepararHoja: debe decir que están las 46 columnas.
B15: 4. Implementar → Nueva implementación → Aplicación web. Ejecutar como: Yo. Acceso: Cualquier persona. Copie la URL /exec.
... B18: No cambie los títulos de la fila 1 de 'Respuestas de formulario 1': el script ubica cada respuesta por ese texto. Si lo cambia, la encuesta avisa con un error en vez de guardar en la columna equivocada.

Sheet Resumen
A1: Encuesta de Cultura de Salud, Seguridad y Ambiente 2026 — Resumen
A2: Se calcula solo con lo que llega a la hoja 'Respuestas de formulario 1'. No escriba en esta hoja.
A4: Respuestas recibidas | B4: =COUNTA('Respuestas de formulario 1'!$A$2:$A$5000) -> 0
A5: Primera respuesta | B5: =IF(B4=0,"",MIN('Respuestas de formulario 1'!$A$2:$A$5000))
A6: Última respuesta | B6: =IF(B4=0,"",MAX('Respuestas de formulario 1'!$A$2:$A$5000))
A8: Planta o sede | B8: Respuestas | C8: % del total
A9: AGG Planta Mondoñedo | B9: =COUNTIF('Respuestas de formulario 1'!$B$2:$B$5000,A9) -> 0 | C9: =IF($B$4=0,"",B9/$B$4)
A10: CEM Planta Nobsa | B10: =COUNTIF('Respuestas de formulario 1'!$B$2:$B$5000,A10) -> 0 | C10: =IF($B$4=0,"",B10/$B$4)
A11: CORPORATIVO Teleport | B11: =COUNTIF('Respuestas de formulario 1'!$B$2:$B$5000,A11) -> 0 | C11: =IF($B$4=0,"",B11/$B$4)
A12: CORPORATIVO Fundación Holcim | B12: =COUNTIF('Respuestas de formulario 1'!$B$2:$B$5000,A12) -> 0 | C12: =IF($B$4=0,"",B12/$B$4)
A13: GEOCYCLE Barrancabermeja | B13: =COUNTIF('Respuestas de formulario 1'!$B$2:$B$5000,A13) -> 0 | C13: =IF($B$4=0,"",B13/$B$4)
A14: GEOCYCLE Nobsa | B14: =COUNTIF('Respuestas de formulario 1'!$B$2:$B$5000,A14) -> 0 | C14: =IF($B$4=0,"",B14/$B$4)
A15: RMX Planta Bello | B15: =COUNTIF('Respuestas de formulario 1'!$B$2:$B$5000,A15) -> 0 | C15: =IF($B$4=0,"",B15/$B$4)
A16: RMX Plantas Valle | B16: =COUNTIF('Respuestas de formulario 1'!$B$2:$B$5000,A16) -> 0 | C16: =IF($B$4=0,"",B16/$B$4)
A17: RMX Planta Chía | B17: =COUNTIF('Respuestas de formulario 1'!$B$2:$B$5000,A17) -> 0 | C17: =IF($B$4=0,"",B17/$B$4)
A18: RMX Plantas Boyaca | B18: =COUNTIF('Respuestas de formulario 1'!$B$2:$B$5000,A18) -> 0 | C18: =IF($B$4=0,"",B18/$B$4)
A19: RMX Planta Puente Aranda | B19: =COUNTIF('Respuestas de formulario 1'!$B$2:$B$5000,A19) -> 0 | C19: =IF($B$4=0,"",B19/$B$4)
A20: RMX Planta Sibaté | B20: =COUNTIF('Respuestas de formulario 1'!$B$2:$B$5000,A20) -> 0 | C20: =IF($B$4=0,"",B20/$B$4)
A21: TQC Tocancipá | B21: =COUNTIF('Respuestas de formulario 1'!$B$2:$B$5000,A21) -> 0 | C21: =IF($B$4=0,"",B21/$B$4)
A23: Vinculación | B23: Respuestas | C23: % del total
A24: Empleado(a) Holcim | B24: =COUNTIF('Respuestas de formulario 1'!$C$2:$C$5000,A24) -> 0 | C24: =IF($B$4=0,"",B24/$B$4)
A25: Contratista Holcim | B25: =COUNTIF('Respuestas de formulario 1'!$C$2:$C$5000,A25) -> 0 | C25: =IF($B$4=0,"",B25/$B$4)
A27: Tipo de cargo | B27: Respuestas | C27: % del total
A28: Director(a) | B28: =COUNTIF('Respuestas de formulario 1'!$D$2:$D$5000,A28) -> 0 | C28: =IF($B$4=0,"",B28/$B$4)
A29: Gerente - Head | B29: =COUNTIF('Respuestas de formulario 1'!$D$2:$D$5000,A29) -> 0 | C29: =IF($B$4=0,"",B29/$B$4)
A30: Jefe - Coordinador(a) | B30: =COUNTIF('Respuestas de formulario 1'!$D$2:$D$5000,A30) -> 0 | C30: =IF($B$4=0,"",B30/$B$4)
A31: Supervisor(a) - Analista | B31: =COUNTIF('Respuestas de formulario 1'!$D$2:$D$5000,A31) -> 0 | C31: =IF($B$4=0,"",B31/$B$4)
A32: Operativo(a) | B32: =COUNTIF('Respuestas de formulario 1'!$D$2:$D$5000,A32) -> 0 | C32: =IF($B$4=0,"",B32/$B$4)
A34: ¿Ha reportado desviaciones sin que se tengan en cuenta? | B34: Respuestas | C34: % del total
A35: Si | B35: =COUNTIF('Respuestas de formulario 1'!$G$2:$G$5000,A35) -> 0 | C35: =IF($B$4=0,"",B35/$B$4)
A36: No | B36: =COUNTIF('Respuestas de formulario 1'!$G$2:$G$5000,A36) -> 0 | C36: =IF($B$4=0,"",B36/$B$4)
A38: Percepción por dimensión | B38: Calificaciones | C38: % Favorable | D38: % Neutral | E38: % Desfavorable
A39: Valores y compromiso HSE | B39: =COUNTA('Respuestas de formulario 1'!$H$2:$K$5000) -> 0 | C39: =IF($B39=0,"",(COUNTIF('Respuestas de formulario 1'!$H$2:$K$5000,"Totalmente de Acuerdo")+COUNTIF('Respuestas de formulario 1'!$H$2:$K$5000,"De acuerdo")+COUNTIF('Respuestas de formulario 1'!$H$2:$K$5000,"Un poco de Acuerdo"))/$B39) | D39: =IF($B39=0,"",(COUNTIF('Respuestas de formulario 1'!$H$2:$K$5000,"Ni de acuerdo ni en desacuerdo"))/$B39) | E39: =IF($B39=0,"",(COUNTIF('Respuestas de formulario 1'!$H$2:$K$5000,"Un poco en Desacuerdo")+COUNTIF('Respuestas de formulario 1'!$H$2:$K$5000,"En Desacuerdo")+COUNTIF('Respuestas de formulario 1'!$H$2:$K$5000,"Totalmente en Desacuerdo"))/$B39)
A40: Procesos operacionales | B40: =COUNTA('Respuestas de formulario 1'!$M$2:$P$5000) -> 0 | C40: =IF($B40=0,"",(COUNTIF('Respuestas de formulario 1'!$M$2:$P$5000,"Totalmente de Acuerdo")+COUNTIF('Respuestas de formulario 1'!$M$2:$P$5000,"De acuerdo")+COUNTIF('Respuestas de formulario 1'!$M$2:$P$5000,"Un poco de Acuerdo"))/$B40) | D40: =IF($B40=0,"",(COUNTIF('Respuestas de formulario 1'!$M$2:$P$5000,"Ni de acuerdo ni en desacuerdo"))/$B40) | E40: =IF($B40=0,"",(COUNTIF('Respuestas de formulario 1'!$M$2:$P$5000,"Un poco en Desacuerdo")+COUNTIF('Respuestas de formulario 1'!$M$2:$P$5000,"En Desacuerdo")+COUNTIF('Respuestas de formulario 1'!$M$2:$P$5000,"Totalmente en Desacuerdo"))/$B40)
A41: Gestión de recursos | B41: =COUNTA('Respuestas de formulario 1'!$R$2:$U$5000) -> 0 | C41: =IF($B41=0,"",(COUNTIF('Respuestas de formulario 1'!$R$2:$U$5000,"Totalmente de Acuerdo")+COUNTIF('Respuestas de formulario 1'!$R$2:$U$5000,"De acuerdo")+COUNTIF('Respuestas de formulario 1'!$R$2:$U$5000,"Un poco de Acuerdo"))/$B41) | D41: =IF($B41=0,"",(COUNTIF('Respuestas de formulario 1'!$R$2:$U$5000,"Ni de acuerdo ni en desacuerdo"))/$B41) | E41: =IF($B41=0,"",(COUNTIF('Respuestas de formulario 1'!$R$2:$U$5000,"Un poco en Desacuerdo")+COUNTIF('Respuestas de formulario 1'!$R$2:$U$5000,"En Desacuerdo")+COUNTIF('Respuestas de formulario 1'!$R$2:$U$5000,"Totalmente en Desacuerdo"))/$B41)
A42: Supervisión | B42: =COUNTA('Respuestas de formulario 1'!$W$2:$Z$5000) -> 0 | C42: =IF($B42=0,"",(COUNTIF('Respuestas de formulario 1'!$W$2:$Z$5000,"Totalmente de Acuerdo")+COUNTIF('Respuestas de formulario 1'!$W$2:$Z$5000,"De acuerdo")+COUNTIF('Respuestas de formulario 1'!$W$2:$Z$5000,"Un poco de Acuerdo"))/$B42) | D42: =IF($B42=0,"",(COUNTIF('Respuestas de formulario 1'!$W$2:$Z$5000,"Ni de acuerdo ni en desacuerdo"))/$B42) | E42: =IF($B42=0,"",(COUNTIF('Respuestas de formulario 1'!$W$2:$Z$5000,"Un poco en Desacuerdo")+COUNTIF('Respuestas de formulario 1'!$W$2:$Z$5000,"En Desacuerdo")+COUNTIF('Respuestas de formulario 1'!$W$2:$Z$5000,"Totalmente en Desacuerdo"))/$B42)
A43: Planificación del trabajo | B43: =COUNTA('Respuestas de formulario 1'!$AB$2:$AE$5000) -> 0 | C43: =IF($B43=0,"",(COUNTIF('Respuestas de formulario 1'!$AB$2:$AE$5000,"Totalmente de Acuerdo")+COUNTIF('Respuestas de formulario 1'!$AB$2:$AE$5000,"De acuerdo")+COUNTIF('Respuestas de formulario 1'!$AB$2:$AE$5000,"Un poco de Acuerdo"))/$B43) | D43: =IF($B43=0,"",(COUNTIF('Respuestas de formulario 1'!$AB$2:$AE$5000,"Ni de acuerdo ni en desacuerdo"))/$B43) | E43: =IF($B43=0,"",(COUNTIF('Respuestas de formulario 1'!$AB$2:$AE$5000,"Un poco en Desacuerdo")+COUNTIF('Respuestas de formulario 1'!$AB$2:$AE$5000,"En Desacuerdo")+COUNTIF('Respuestas de formulario 1'!$AB$2:$AE$5000,"Totalmente en Desacuerdo"))/$B43)
A44: Abordaje de problemas y peligros | B44: =COUNTA('Respuestas de formulario 1'!$AG$2:$AJ$5000) -> 0 | C44: =IF($B44=0,"",(COUNTIF('Respuestas de formulario 1'!$AG$2:$AJ$5000,"Totalmente de Acuerdo")+COUNTIF('Respuestas de formulario 1'!$AG$2:$AJ$5000,"De acuerdo")+COUNTIF('Respuestas de formulario 1'!$AG$2:$AJ$5000,"Un poco de Acuerdo"))/$B44) | D44: =IF($B44=0,"",(COUNTIF('Respuestas de formulario 1'!$AG$2:$AJ$5000,"Ni de acuerdo ni en desacuerdo"))/$B44) | E44: =IF($B44=0,"",(COUNTIF('Respuestas de formulario 1'!$AG$2:$AJ$5000,"Un poco en Desacuerdo")+COUNTIF('Respuestas de formulario 1'!$AG$2:$AJ$5000,"En Desacuerdo")+COUNTIF('Respuestas de formulario 1'!$AG$2:$AJ$5000,"Totalmente en Desacuerdo"))/$B44)
A45: Cumplimiento de reglas | B45: =COUNTA('Respuestas de formulario 1'!$AL$2:$AO$5000) -> 0 | C45: =IF($B45=0,"",(COUNTIF('Respuestas de formulario 1'!$AL$2:$AO$5000,"Totalmente de Acuerdo")+COUNTIF('Respuestas de formulario 1'!$AL$2:$AO$5000,"De acuerdo")+COUNTIF('Respuestas de formulario 1'!$AL$2:$AO$5000,"Un poco de Acuerdo"))/$B45) | D45: =IF($B45=0,"",(COUNTIF('Respuestas de formulario 1'!$AL$2:$AO$5000,"Ni de acuerdo ni en desacuerdo"))/$B45) | E45: =IF($B45=0,"",(COUNTIF('Respuestas de formulario 1'!$AL$2:$AO$5000,"Un poco en Desacuerdo")+COUNTIF('Respuestas de formulario 1'!$AL$2:$AO$5000,"En Desacuerdo")+COUNTIF('Respuestas de formulario 1'!$AL$2:$AO$5000,"Totalmente en Desacuerdo"))/$B45)
A46: Evaluación subjetiva de riesgos | B46: =COUNTA('Respuestas de formulario 1'!$AQ$2:$AS$5000) -> 0 | C46: =IF($B46=0,"",(COUNTIF('Respuestas de formulario 1'!$AQ$2:$AS$5000,"Totalmente de Acuerdo")+COUNTIF('Respuestas de formulario 1'!$AQ$2:$AS$5000,"De acuerdo")+COUNTIF('Respuestas de formulario 1'!$AQ$2:$AS$5000,"Un poco de Acuerdo"))/$B46) | D46: =IF($B46=0,"",(COUNTIF('Respuestas de formulario 1'!$AQ$2:$AS$5000,"Ni de acuerdo ni en desacuerdo"))/$B46) | E46: =IF($B46=0,"",(COUNTIF('Respuestas de formulario 1'!$AQ$2:$AS$5000,"Un poco en Desacuerdo")+COUNTIF('Respuestas de formulario 1'!$AQ$2:$AS$5000,"En Desacuerdo")+COUNTIF('Respuestas de formulario 1'!$AQ$2:$AS$5000,"Totalmente en Desacuerdo"))/$B46)
...

Sheet Respuestas de formulario 1
A1: Marca temporal | B1: ¿En cuál planta o sede de trabajo está ubicado(a)? | C1: Usted es: | D1: Qué tipo de cargo desempeña en sus labores | E1: Cúal es su rango de Edad en años | F1: Número de años que lleva trabajando en Holcim Colombia | G1: Ha reportado alguna desviación en Salud, Seguridad o Ambiente sin que esta haya sido tenido en cuenta | H1: Mi supervisor/gerente apoya los más altos estándares posibles de salud, seguridad y ambiente (HSE). | I1: La salud, seguridad y ambiente (HSE) son una prioridad en mi trabajo. | J1: La gerencia se preocupa por la salud, seguridad y ambiente (HSE), incluso si no hay incidentes ni accidentes. | K1: La gerencia y los supervisores son modelos a seguir para los comportamientos esperados en materia de salud, seguridad y ambiente (HSE). | L1: Por favor comparta aquí sus comentarios sobre VALORES Y COMPROMISO HSE: | M1: Nuestra comunicación en temas de salud, seguridad y ambiente (HSE) es efectiva en todos los niveles de la empresa (De arriba hacia abajo, de abajo hacia arriba y de igual a igual). | N1: La alta gerencia es consciente de los problemas que enfrentan los trabajadores en el campo y actúa para resolverlos. | O1: Las tareas se evalúan periódicamente para identificar y gestionar los riesgos en mi lugar de trabajo. | P1: Se motiva e invita a los empleados a involucrarse en la mejora de los procesos de trabajo en función de los riesgos identificados. | Q1: Por favor comparta aquí sus comentarios sobre PROCESOS OPERACIONALES: | R1: En Holcim Colombia se está invirtiendo activamente recursos para mejorar la salud, seguridad y ambiente. | S1: Holcim Colombia contrata trabajadores alineados con los valores de HSE y brinda oportunidades de capacitación y aprendizaje. | T1: Holcim Colombia asegura que las herramientas y los equipos sean eficientes, apropiados y seguros de usar. | U1: Holcim Colombia valora el tiempo invertido en mejorar la salud, la seguridad y el medio ambiente. | V1: Por favor comparta aquí sus comentarios sobre GESTIÓN DE RECURSOS: | W1: Los supervisores alientan a los trabajadores a reportar e informar cualquier problema o inquietud. | X1: Los supervisores alientan a los trabajadores a dedicar tiempo para la capacitación y el desarrollo personal. | Y1: Los trabajadores reciben suficiente capacitación e instrucciones para realizar su trabajo de manera segura. | Z1: Los supervisores están presentes en campo y brindan supervisión regular y comentarios constructivos. | AA1: Por favor comparta aquí sus comentarios sobre SUPERVISIÓN: | AB1: Se informa a los trabajadores sobre los peligros potenciales asociados con las actividades laborales. | AC1: Los supervisores tratan de distribuir la carga de trabajo de manera uniforme entre los trabajadores. | AD1: Los supervisores monitorean de cerca la competencia para garantizar que los trabajadores estén calificados para realizar las tareas asignadas. | AE1: Me proporcionan la información, el equipo y el tiempo apropiado para realizar mi trabajo de manera segura. | AF1: Por favor comparta aquí sus comentarios sobre PLANIFICACIÓN DEL TRABAJO: | AG1: Los supervisores constantemente hacen responsables a los trabajadores que actúan de manera insegura, incluso si sus acciones ahorraron tiempo o dinero. | AH1: Cuando los trabajadores reportan un problema de salud, seguridad y medio ambiente, los supervisores actúan rápidamente para corregir el problema. | AI1: Los supervisores no son permisivos con los trabajadores que violan los procedimientos y reglas de salud, seguridad y medio ambiente. | AJ1: Cuando es necesario, las consecuencias disciplinarias se aplican a los empleados en cualquier nivel de la organización. | AK1: Por favor comparta aquí sus comentarios sobre ABORDAJE DE PROBLEMAS Y PELIGROS: | AL1: Los supervisores animan a los trabajadores a detener los trabajos que no sean seguros. | AM1: Los supervisores dan ejemplo en el cumplimiento de Reglas y estándares de salud, seguridad y medio ambiente. | AN1: Los supervisores nunca firman evaluaciones de Riesgos (Permisos de trabajo, ATS o ITS) que están incompletos o inexactos. | AO1: Los supervisores siempre siguen las reglas de salud, seguridad y ambiente (HSE). | AP1: Por favor comparta aquí sus comentarios sobre CUMPLIMIENTO DE REGLAS: | AQ1: Es poco probable que me lesione en el trabajo durante los próximos 12 meses. | AR1: Es poco probable que uno de mis compañeros de trabajo o contratistas se lesionen en el trabajo en los próximos 12 meses. | AS1: Es poco probable que ocurra un incidente o accidente en los próximos 12 meses. | AT1: Por favor comparta aquí sus comentarios sobre EVALUACIÓN SUBJETIVA DE RIESGOS:

Sheet Reportes de problemas
A1: Marca temporal | B1: Tipo | C1: Descripción | D1: Pantalla | E1: Contacto | F1: Navegador | G1: Tamaño de pantalla | H1: Tema | I1: Último error | J1: Estado

Sheet Diccionario
A1: Col. | B1: N.º | C1: Sección | D1: Pregunta (título exacto de la columna) | E1: Tipo | F1: Valores que puede tener
A2: A | B2: 1 | C2: Registro | D2: Marca temporal | E2: Fecha y hora | F2: La escribe sola la encuesta
A3: B | B3: 2 | C3: Datos generales | D3: ¿En cuál planta o sede de trabajo está ubicado(a)? | E3: Opción | F3: AGG Planta Mondoñedo · CEM Planta Nobsa · CORPORATIVO Teleport · CORPORATIVO Fundación Holcim · GEOCYCLE Barrancabermeja · GEOCYCLE Nobsa · RMX Planta Bello · RMX Plantas Valle · RMX Planta Chía · RMX Plantas Boyaca · RMX Planta Puente Aranda · RMX Planta Sibaté · TQC Tocancipá
A4: C | B4: 3 | C4: Datos generales | D4: Usted es: | E4: Opción | F4: Empleado(a) Holcim · Contratista Holcim
A5: D | B5: 4 | C5: Datos generales | D5: Qué tipo de cargo desempeña en sus labores | E5: Opción | F5: Director(a) · Gerente - Head · Jefe - Coordinador(a) · Supervisor(a) - Analista · Operativo(a)
A6: E | B6: 5 | C6: Datos generales | D6: Cúal es su rango de Edad en años | E6: Opción | F6: Menos de 20 · 20 - 30 · 31 - 40 · 41 - 50 · 51 - 60 · + 61
A7: F | B7: 6 | C7: Datos generales | D7: Número de años que lleva trabajando en Holcim Colombia | E7: Opción | F7: 0 a 1 · 1 a 5 · 6 a 10 · 11 a 15 · 16 a 20 · + 20
A8: G | B8: 7 | C8: Datos generales | D8: Ha reportado alguna desviación en Salud, Seguridad o Ambiente sin que esta haya sido tenido en cuenta | E8: Opción | F8: Si · No
A9: H | B9: 8 | C9: Valores y compromiso HSE | D9: Mi supervisor/gerente apoya los más altos estándares posibles de salud, seguridad y ambiente (HSE). | E9: Escala de acuerdo | F9: Totalmente de Acuerdo · De acuerdo · Un poco de Acuerdo · Ni de acuerdo ni en desacuerdo · Un poco en Desacuerdo · En Desacuerdo · Totalmente en Desacuerdo
A10: I | B10: 9 | C10: Valores y compromiso HSE | D10: La salud, seguridad y ambiente (HSE) son una prioridad en mi trabajo. | E10: Escala de acuerdo | F10: Totalmente de Acuerdo · De acuerdo · Un poco de Acuerdo · Ni de acuerdo ni en desacuerdo · Un poco en Desacuerdo · En Desacuerdo · Totalmente en Desacuerdo
A11: J | B11: 10 | C11: Valores y compromiso HSE | D11: La gerencia se preocupa por la salud, seguridad y ambiente (HSE), incluso si no hay incidentes ni accidentes. | E11: Escala de acuerdo | F11: Totalmente de Acuerdo · De acuerdo · Un poco de Acuerdo · Ni de acuerdo ni en desacuerdo · Un poco en Desacuerdo · En Desacuerdo · Totalmente en Desacuerdo
A12: K | B12: 11 | C12: Valores y compromiso HSE | D12: La gerencia y los supervisores son modelos a seguir para los comportamientos esperados en materia de salud, seguridad y ambiente (HSE). | E12: Escala de acuerdo | F12: Totalmente de Acuerdo · De acuerdo · Un poco de Acuerdo · Ni de acuerdo ni en desacuerdo · Un poco en Desacuerdo · En Desacuerdo · Totalmente en Desacuerdo
A13: L | B13: 12 | C13: Valores y compromiso HSE | D13: Por favor comparta aquí sus comentarios sobre VALORES Y COMPROMISO HSE: | E13: Texto (opcional) | F13: Comentario libre, hasta 1000 caracteres
... A47: AT | B47: 46 | C47: Evaluación subjetiva de riesgos | D47: Por favor comparta aquí sus comentarios sobre EVALUACIÓN SUBJETIVA DE RIESGOS: | E47: Texto (opcional) | F47: Comentario libre, hasta 1000 caracteres
